2024-05-15 17:00:04,369 ERROR: Exception on /login [GET] [in /home/costamay/.local/share/virtualenvs/flask-app-VED2Ybei/lib/python3.8/site-packages/flask/app.py:838]
Traceback (most recent call last):
  File "/home/costamay/.local/share/virtualenvs/flask-app-VED2Ybei/lib/python3.8/site-packages/flask/app.py", line 1473, in wsgi_app
    response = self.full_dispatch_request()
  File "/home/costamay/.local/share/virtualenvs/flask-app-VED2Ybei/lib/python3.8/site-packages/flask/app.py", line 882, in full_dispatch_request
    rv = self.handle_user_exception(e)
  File "/home/costamay/.local/share/virtualenvs/flask-app-VED2Ybei/lib/python3.8/site-packages/flask/app.py", line 880, in full_dispatch_request
    rv = self.dispatch_request()
  File "/home/costamay/.local/share/virtualenvs/flask-app-VED2Ybei/lib/python3.8/site-packages/flask/app.py", line 865, in dispatch_request
    return self.ensure_sync(self.view_functions[rule.endpoint])(**view_args)  # type: ignore[no-any-return]
  File "/home/costamay/Documents/Developmentt/flask-by-miguel/flask-app/app/routes.py", line 55, in login
    return render_template('login.html', title='Sign In', form=form)
  File "/home/costamay/.local/share/virtualenvs/flask-app-VED2Ybei/lib/python3.8/site-packages/flask/templating.py", line 150, in render_template
    return _render(app, template, context)
  File "/home/costamay/.local/share/virtualenvs/flask-app-VED2Ybei/lib/python3.8/site-packages/flask/templating.py", line 131, in _render
    rv = template.render(context)
  File "/home/costamay/.local/share/virtualenvs/flask-app-VED2Ybei/lib/python3.8/site-packages/jinja2/environment.py", line 1304, in render
    self.environment.handle_exception()
  File "/home/costamay/.local/share/virtualenvs/flask-app-VED2Ybei/lib/python3.8/site-packages/jinja2/environment.py", line 939, in handle_exception
    raise rewrite_traceback_stack(source=source)
  File "/home/costamay/Documents/Developmentt/flask-by-miguel/flask-app/app/templates/login.html", line 1, in top-level template code
    {% extends 'base.html' %}
  File "/home/costamay/.local/share/virtualenvs/flask-app-VED2Ybei/lib/python3.8/site-packages/jinja2/environment.py", line 939, in handle_exception
    raise rewrite_traceback_stack(source=source)
  File "/home/costamay/Documents/Developmentt/flask-by-miguel/flask-app/app/templates/base.html", line 1, in template
    {% comment %} <!doctype html>
jinja2.exceptions.TemplateSyntaxError: Encountered unknown tag 'comment'.
2024-05-15 17:00:14,045 ERROR: Exception on /login [GET] [in /home/costamay/.local/share/virtualenvs/flask-app-VED2Ybei/lib/python3.8/site-packages/flask/app.py:838]
Traceback (most recent call last):
  File "/home/costamay/.local/share/virtualenvs/flask-app-VED2Ybei/lib/python3.8/site-packages/flask/app.py", line 1473, in wsgi_app
    response = self.full_dispatch_request()
  File "/home/costamay/.local/share/virtualenvs/flask-app-VED2Ybei/lib/python3.8/site-packages/flask/app.py", line 882, in full_dispatch_request
    rv = self.handle_user_exception(e)
  File "/home/costamay/.local/share/virtualenvs/flask-app-VED2Ybei/lib/python3.8/site-packages/flask/app.py", line 880, in full_dispatch_request
    rv = self.dispatch_request()
  File "/home/costamay/.local/share/virtualenvs/flask-app-VED2Ybei/lib/python3.8/site-packages/flask/app.py", line 865, in dispatch_request
    return self.ensure_sync(self.view_functions[rule.endpoint])(**view_args)  # type: ignore[no-any-return]
  File "/home/costamay/Documents/Developmentt/flask-by-miguel/flask-app/app/routes.py", line 55, in login
    return render_template('login.html', title='Sign In', form=form)
  File "/home/costamay/.local/share/virtualenvs/flask-app-VED2Ybei/lib/python3.8/site-packages/flask/templating.py", line 150, in render_template
    return _render(app, template, context)
  File "/home/costamay/.local/share/virtualenvs/flask-app-VED2Ybei/lib/python3.8/site-packages/flask/templating.py", line 131, in _render
    rv = template.render(context)
  File "/home/costamay/.local/share/virtualenvs/flask-app-VED2Ybei/lib/python3.8/site-packages/jinja2/environment.py", line 1304, in render
    self.environment.handle_exception()
  File "/home/costamay/.local/share/virtualenvs/flask-app-VED2Ybei/lib/python3.8/site-packages/jinja2/environment.py", line 939, in handle_exception
    raise rewrite_traceback_stack(source=source)
  File "/home/costamay/Documents/Developmentt/flask-by-miguel/flask-app/app/templates/login.html", line 1, in top-level template code
    {% extends 'base.html' %}
  File "/home/costamay/.local/share/virtualenvs/flask-app-VED2Ybei/lib/python3.8/site-packages/jinja2/environment.py", line 939, in handle_exception
    raise rewrite_traceback_stack(source=source)
  File "/home/costamay/Documents/Developmentt/flask-by-miguel/flask-app/app/templates/base.html", line 1, in template
    {% comment %} <!doctype html>
jinja2.exceptions.TemplateSyntaxError: Encountered unknown tag 'comment'.
2024-05-15 17:01:02,850 INFO: App startup [in /home/costamay/Documents/Developmentt/flask-by-miguel/flask-app/app/__init__.py:45]
2024-05-15 17:03:20,264 INFO: App startup [in /home/costamay/Documents/Developmentt/flask-by-miguel/flask-app/app/__init__.py:45]
2024-05-15 17:04:25,655 ERROR: Exception on /index [GET] [in /home/costamay/.local/share/virtualenvs/flask-app-VED2Ybei/lib/python3.8/site-packages/flask/app.py:838]
Traceback (most recent call last):
  File "/home/costamay/.local/share/virtualenvs/flask-app-VED2Ybei/lib/python3.8/site-packages/flask/app.py", line 1473, in wsgi_app
    response = self.full_dispatch_request()
  File "/home/costamay/.local/share/virtualenvs/flask-app-VED2Ybei/lib/python3.8/site-packages/flask/app.py", line 882, in full_dispatch_request
    rv = self.handle_user_exception(e)
  File "/home/costamay/.local/share/virtualenvs/flask-app-VED2Ybei/lib/python3.8/site-packages/flask/app.py", line 880, in full_dispatch_request
    rv = self.dispatch_request()
  File "/home/costamay/.local/share/virtualenvs/flask-app-VED2Ybei/lib/python3.8/site-packages/flask/app.py", line 865, in dispatch_request
    return self.ensure_sync(self.view_functions[rule.endpoint])(**view_args)  # type: ignore[no-any-return]
  File "/home/costamay/.local/share/virtualenvs/flask-app-VED2Ybei/lib/python3.8/site-packages/flask_login/utils.py", line 290, in decorated_view
    return current_app.ensure_sync(func)(*args, **kwargs)
  File "/home/costamay/Documents/Developmentt/flask-by-miguel/flask-app/app/routes.py", line 36, in index
    return render_template('index.html', title="Home", form=form, posts=posts.items, next_url=next_url, prev_url=prev_url)
  File "/home/costamay/.local/share/virtualenvs/flask-app-VED2Ybei/lib/python3.8/site-packages/flask/templating.py", line 150, in render_template
    return _render(app, template, context)
  File "/home/costamay/.local/share/virtualenvs/flask-app-VED2Ybei/lib/python3.8/site-packages/flask/templating.py", line 131, in _render
    rv = template.render(context)
  File "/home/costamay/.local/share/virtualenvs/flask-app-VED2Ybei/lib/python3.8/site-packages/jinja2/environment.py", line 1304, in render
    self.environment.handle_exception()
  File "/home/costamay/.local/share/virtualenvs/flask-app-VED2Ybei/lib/python3.8/site-packages/jinja2/environment.py", line 939, in handle_exception
    raise rewrite_traceback_stack(source=source)
  File "/home/costamay/Documents/Developmentt/flask-by-miguel/flask-app/app/templates/index.html", line 2, in top-level template code
    {% import "bootstrap_wtf.html" as wtf %}
  File "/home/costamay/Documents/Developmentt/flask-by-miguel/flask-app/app/templates/base.html", line 58, in top-level template code
    {% block content %}{% endblock %}
  File "/home/costamay/Documents/Developmentt/flask-by-miguel/flask-app/app/templates/index.html", line 10, in block 'content'
    {% include '_post.html' %}
  File "/home/costamay/Documents/Developmentt/flask-by-miguel/flask-app/app/templates/_post.html", line 4, in top-level template code
    <a href="{{ url_for('user', username=post.author.username) }}">
  File "/home/costamay/.local/share/virtualenvs/flask-app-VED2Ybei/lib/python3.8/site-packages/jinja2/environment.py", line 487, in getattr
    return getattr(obj, attribute)
jinja2.exceptions.UndefinedError: 'app.models.Post object' has no attribute 'author'
2024-05-15 17:07:34,820 INFO: App startup [in /home/costamay/Documents/Developmentt/flask-by-miguel/flask-app/app/__init__.py:45]
