2024-05-09 23:37:32,159 ERROR: Exception on /index [GET] [in /home/costamay/.local/share/virtualenvs/flask-app-VED2Ybei/lib/python3.8/site-packages/flask/app.py:838]
Traceback (most recent call last):
  File "/home/costamay/.local/share/virtualenvs/flask-app-VED2Ybei/lib/python3.8/site-packages/flask/app.py", line 1473, in wsgi_app
    response = self.full_dispatch_request()
  File "/home/costamay/.local/share/virtualenvs/flask-app-VED2Ybei/lib/python3.8/site-packages/flask/app.py", line 882, in full_dispatch_request
    rv = self.handle_user_exception(e)
  File "/home/costamay/.local/share/virtualenvs/flask-app-VED2Ybei/lib/python3.8/site-packages/flask/app.py", line 880, in full_dispatch_request
    rv = self.dispatch_request()
  File "/home/costamay/.local/share/virtualenvs/flask-app-VED2Ybei/lib/python3.8/site-packages/flask/app.py", line 865, in dispatch_request
    return self.ensure_sync(self.view_functions[rule.endpoint])(**view_args)  # type: ignore[no-any-return]
  File "/home/costamay/.local/share/virtualenvs/flask-app-VED2Ybei/lib/python3.8/site-packages/flask_login/utils.py", line 290, in decorated_view
    return current_app.ensure_sync(func)(*args, **kwargs)
  File "/home/costamay/Documents/Developmentt/flask-by-miguel/flask-app/app/routes.py", line 29, in index
    posts = db.paginate(current_user.following_posts(), page=page, per_page=app.config['POSTS_PER_PAGE'], error=False)
TypeError: paginate() got an unexpected keyword argument 'error'
2024-05-09 23:38:07,818 INFO: App startup [in /home/costamay/Documents/Developmentt/flask-by-miguel/flask-app/app/__init__.py:43]
2024-05-10 18:04:07,133 INFO: App startup [in /home/costamay/Documents/Developmentt/flask-by-miguel/flask-app/app/__init__.py:45]
2024-05-10 18:15:17,802 INFO: App startup [in /home/costamay/Documents/Developmentt/flask-by-miguel/flask-app/app/__init__.py:45]
2024-05-15 14:48:51,256 INFO: App startup [in /home/costamay/Documents/Developmentt/flask-by-miguel/flask-app/app/__init__.py:45]
2024-05-15 15:04:05,642 INFO: App startup [in /home/costamay/Documents/Developmentt/flask-by-miguel/flask-app/app/__init__.py:45]
2024-05-15 15:11:31,060 INFO: App startup [in /home/costamay/Documents/Developmentt/flask-by-miguel/flask-app/app/__init__.py:45]
2024-05-15 15:15:54,700 INFO: App startup [in /home/costamay/Documents/Developmentt/flask-by-miguel/flask-app/app/__init__.py:45]
2024-05-15 15:19:42,063 ERROR: Exception on /reset_password_request [POST] [in /home/costamay/.local/share/virtualenvs/flask-app-VED2Ybei/lib/python3.8/site-packages/flask/app.py:838]
Traceback (most recent call last):
  File "/home/costamay/.local/share/virtualenvs/flask-app-VED2Ybei/lib/python3.8/site-packages/flask/app.py", line 1473, in wsgi_app
    response = self.full_dispatch_request()
  File "/home/costamay/.local/share/virtualenvs/flask-app-VED2Ybei/lib/python3.8/site-packages/flask/app.py", line 882, in full_dispatch_request
    rv = self.handle_user_exception(e)
  File "/home/costamay/.local/share/virtualenvs/flask-app-VED2Ybei/lib/python3.8/site-packages/flask/app.py", line 880, in full_dispatch_request
    rv = self.dispatch_request()
  File "/home/costamay/.local/share/virtualenvs/flask-app-VED2Ybei/lib/python3.8/site-packages/flask/app.py", line 865, in dispatch_request
    return self.ensure_sync(self.view_functions[rule.endpoint])(**view_args)  # type: ignore[no-any-return]
  File "/home/costamay/Documents/Developmentt/flask-by-miguel/flask-app/app/routes.py", line 170, in reset_password_request
    send_password_reset_email(user)
  File "/home/costamay/Documents/Developmentt/flask-by-miguel/flask-app/app/email.py", line 18, in send_password_reset_email
    token = user.get_reset_pasword_token()
AttributeError: 'User' object has no attribute 'get_reset_pasword_token'
2024-05-15 15:22:42,962 INFO: App startup [in /home/costamay/Documents/Developmentt/flask-by-miguel/flask-app/app/__init__.py:45]
2024-05-15 15:23:00,989 ERROR: Exception on /reset_password_request [POST] [in /home/costamay/.local/share/virtualenvs/flask-app-VED2Ybei/lib/python3.8/site-packages/flask/app.py:838]
Traceback (most recent call last):
  File "/home/costamay/.local/share/virtualenvs/flask-app-VED2Ybei/lib/python3.8/site-packages/flask/app.py", line 1473, in wsgi_app
    response = self.full_dispatch_request()
  File "/home/costamay/.local/share/virtualenvs/flask-app-VED2Ybei/lib/python3.8/site-packages/flask/app.py", line 882, in full_dispatch_request
    rv = self.handle_user_exception(e)
  File "/home/costamay/.local/share/virtualenvs/flask-app-VED2Ybei/lib/python3.8/site-packages/flask/app.py", line 880, in full_dispatch_request
    rv = self.dispatch_request()
  File "/home/costamay/.local/share/virtualenvs/flask-app-VED2Ybei/lib/python3.8/site-packages/flask/app.py", line 865, in dispatch_request
    return self.ensure_sync(self.view_functions[rule.endpoint])(**view_args)  # type: ignore[no-any-return]
  File "/home/costamay/Documents/Developmentt/flask-by-miguel/flask-app/app/routes.py", line 170, in reset_password_request
    send_password_reset_email(user)
  File "/home/costamay/Documents/Developmentt/flask-by-miguel/flask-app/app/email.py", line 21, in send_password_reset_email
    send_email('[App] Reset Your Email',
TypeError: send_email() got an unexpected keyword argument 'recepients'
2024-05-15 15:25:39,306 INFO: App startup [in /home/costamay/Documents/Developmentt/flask-by-miguel/flask-app/app/__init__.py:45]
2024-05-15 15:29:34,571 INFO: App startup [in /home/costamay/Documents/Developmentt/flask-by-miguel/flask-app/app/__init__.py:45]
2024-05-15 15:52:27,803 INFO: App startup [in /home/costamay/Documents/Developmentt/flask-by-miguel/flask-app/app/__init__.py:45]
2024-05-15 15:59:25,731 INFO: App startup [in /home/costamay/Documents/Developmentt/flask-by-miguel/flask-app/app/__init__.py:45]
